Workbook

Sheet Banco de preguntas
A1: ID | B1: Bloque | C1: Artículo/Regla | D1: Enunciado | E1: Opción A | F1: Opción B | G1: Opción C | H1: Correcta | I1: Explicación | J1: Referencia | K1: Fuente | L1: Dificultad | M1: Página
A2: BC-001 | B2: normativa | C2: Art. 20 | D2: Según las Bases de Competición, ¿qué obligación tiene el club local respecto a la asistencia sanitaria en cada partido? | E2: Disponer de un médico colegiado en plantilla y una ambulancia de soporte vital básico. | F2: Disponer únicamente de un fisioterapeuta en el banquillo local. | G2: Disponer de una ambulancia solo cuando lo solicite el equipo visitante. | H2: A | I2: El Artículo 20 exige médico colegiado obligatorio presente como local y ambulancia de soporte vital básico aportada por el club local. | J2: Art. 20 | K2: Resumen_Articulos_Bases_Competicion_20-30.pdf | L2: 4
A3: BC-002 | B3: normativa | C3: Art. 20 | D3: ¿Quién es responsable, entre otras funciones, del control antidopaje según el Artículo 20 de las Bases de Competición? | E3: El delegado de campo. | F3: El médico colegiado de la plantilla. | G3: El cuarto árbitro. | H3: B | I3: El médico colegiado obligatorio en plantilla es responsable, entre otras cosas, del control antidopaje. | J3: Art. 20 | K3: Resumen_Articulos_Bases_Competicion_20-30.pdf | L3: 1
A4: BC-003 | B4: normativa | C4: Art. 23 | D4: ¿Cuál es el número mínimo de futbolistas de la plantilla de la categoría necesario para poder empezar un partido según el Artículo 23 de las Bases de Competición? | E4: 7 futbolistas. | F4: 8 futbolistas. | G4: 9 futbolistas. | H4: A | I4: El Artículo 23 exige un mínimo de 7 futbolistas de la plantilla de la categoría para poder empezar el partido; en caso contrario, incomparecencia. | J4: Art. 23 | K4: Resumen_Articulos_Bases_Competicion_20-30.pdf | L4: 2
A5: BC-004 | B5: normativa | C5: Art. 23 | D5: Durante un partido, ¿cuántos futbolistas como máximo pueden no pertenecer a la plantilla de la categoría en que militan, según el Artículo 23 de las Bases de Competición? | E5: 2 futbolistas. | F5: 4 futbolistas. | G5: 6 futbolistas. | H5: B | I5: El Artículo 23 fija un máximo de 4 futbolistas que no pertenezcan a la plantilla de la categoría durante el partido. | J5: Art. 23 | K5: Resumen_Articulos_Bases_Competicion_20-30.pdf | L5: 4
A6: BC-005 | B6: normativa | C6: Art. 23 | D6: Si un equipo se presenta con menos de 7 futbolistas de su plantilla de categoría, ¿qué situación se produce según el Artículo 23 de las Bases de Competición? | E6: Se retrasa el inicio 30 minutos. | F6: Incomparecencia. | G6: Se juega igualmente con autorización del árbitro. | H6: B | I6: El mínimo de 7 futbolistas de la plantilla de la categoría es requisito para empezar; de no cumplirse, se considera incomparecencia. | J6: Art. 23 | K6: Resumen_Articulos_Bases_Competicion_20-30.pdf | L6: 4
A7: BC-006 | B7: normativa | C7: Art. 24 | D7: ¿Cuál es el número máximo de suplentes posibles según el Artículo 24 de las Bases de Competición? | E7: 7 suplentes. | F7: 9 suplentes. | G7: 12 suplentes. | H7: B | I7: El Artículo 24 establece un máximo de 9 suplentes posibles. | J7: Art. 24 | K7: Resumen_Articulos_Bases_Competicion_20-30.pdf | L7: 1
A8: BC-007 | B8: normativa | C8: Art. 24 | D8: ¿Cuántas sustituciones efectivas como máximo, y en cuántas interrupciones por equipo, permite el Artículo 24 de las Bases de Competición? | E8: 3 sustituciones en 2 interrupciones. | F8: 5 sustituciones en 3 interrupciones. | G8: 6 sustituciones en 4 interrupciones. | H8: B | I8: El Artículo 24 permite máximo 5 sustituciones efectivas, distribuidas en 3 interrupciones por equipo, previa autorización arbitral. | J8: Art. 24 | K8: Resumen_Articulos_Bases_Competicion_20-30.pdf | L8: 2
A9: BC-008 | B9: normativa | C9: Art. 24 | D9: En el Play Off de Ascenso, si el partido llega a la prórroga, ¿qué sustituciones adicionales contempla el Artículo 24 de las Bases de Competición? | E9: 2 sustituciones adicionales y 2 oportunidades más. | F9: 1 sustitución adicional y 1 oportunidad de sustitución más. | G9: No se permite ninguna sustitución adicional en prórroga. | H9: B | I9: En Play Off de Ascenso y Torneo de Permanencia, si hay prórroga se concede 1 sustitución adicional y 1 oportunidad de sustitución más. | J9: Art. 24 | K9: Resumen_Articulos_Bases_Competicion_20-30.pdf | L9: 4
A10: BC-009 | B10: normativa | C10: Art. 24 | D10: ¿Cuántos futbolistas como máximo pueden calentar por equipo en banda junto al preparador físico, según el Artículo 24 de las Bases de Competición? | E10: 3 futbolistas. | F10: 5 futbolistas. | G10: 7 futbolistas. | H10: B | I10: El Artículo 24 fija un máximo de 5 futbolistas por equipo calentando en banda junto al preparador físico. | J10: Art. 24 | K10: Resumen_Articulos_Bases_Competicion_20-30.pdf | L10: 2
A11: BC-010 | B11: normativa | C11: Art. 24 | D11: ¿Se puede sustituir a un futbolista que ha sido expulsado, según el Artículo 24 de las Bases de Competición? | E11: Sí, siempre que queden sustituciones disponibles. | F11: No, en ningún caso. | G11: Sí, pero solo en la segunda parte. | H11: B | I11: El Artículo 24 establece expresamente que no se puede sustituir a un futbolista expulsado. | J11: Art. 24 | K11: Resumen_Articulos_Bases_Competicion_20-30.pdf | L11: 4
A12: BC-011 | B12: normativa | C12: Art. 24 | D12: ¿Quién puede acceder al vestuario según el Artículo 24 de las Bases de Competición? | E12: Cualquier aficionado o socio acreditado por el club, sin ninguna restricción adicional. | F12: Solo miembros autorizados: equipo arbitral, futbolistas inscritos en acta, técnicos, médicos, fisioterapeutas, delegados, etc. | G12: Únicamente los capitanes de ambos equipos y el delegado de campo del club local. | H12: B | I12: El Artículo 24 limita el acceso al vestuario a los miembros autorizados expresamente enumerados. | J12: Art. 24 | K12: Resumen_Articulos_Bases_Competicion_20-30.pdf | L12: 2
A13: BC-012 | B13: normativa | C13: Art. 25 | D13: ¿A qué normativa de juego están sujetos obligatoriamente los partidos según el Artículo 25 de las Bases de Competición? | E13: A las Reglas de Juego de la IFAB vigentes en la temporada en curso. | F13: A las Reglas de Juego que decida cada federación autonómica. | G13: A un reglamento propio de la RFEF independiente de la IFAB. | H13: A | I13: El Artículo 25 establece la sujeción obligatoria a las Reglas de Juego de la IFAB vigentes en la temporada en curso. | J13: Art. 25 | K13: Resumen_Articulos_Bases_Competicion_20-30.pdf | L13: 4
... A93: RC-041 | B93: normativa | C93: Art. 150 | D93: ¿Cuántas personas como máximo puede haber en el banquillo técnico adicional, situado a 5 metros del principal, según el Artículo 150 del Reglamento de Competiciones? | E93: 3 personas. | F93: 5 personas. | G93: 7 personas. | H93: B | I93: El Artículo 150 fija un máximo de 5 personas en el banquillo técnico adicional, situado a 5 metros del principal. | J93: Art. 150 | K93: ResumenReglamentoCompeticiones.pdf | L93: 2
A94: RC-042 | B94: normativa | C94: Art. 150 | D94: Un futbolista es expulsado. Según el Artículo 150 del Reglamento de Competiciones: | E94: Debe dirigirse a los vestuarios, sin poder presenciar el partido desde la grada. | F94: Puede presenciar el resto del partido desde la grada de público. | G94: Puede permanecer en el banquillo, mientras no intervenga en el juego. | H94: A | I94: Art. 150.5: «Los que resulten ser expulsados/as, deberán dirigirse a los vestuarios sin posibilidad de presenciar el partido desde la grada». La excepción afecta solo a médicos, Graduado/a en Enfermería y fisioterapeuta, que no pueden seguir en el banquillo pero sí presenciar el partido. | J94: Art. 150 | K94: ReglamentoDeCompeticiones2025.pdf | L94: 4 | M94: 124
A95: RC-043 | B95: normativa | C95: Art. 151 | D95: ¿Quién no puede ejercer como delegado de campo, según el Artículo 151 del Reglamento de Competiciones? | E95: Un miembro de la Junta Directiva de la RFEF. | F95: El entrenador titular del equipo local. | G95: Cualquier futbolista suplente. | H95: A | I95: El Artículo 151 prohíbe que sea delegado de campo un miembro de la Junta Directiva de la RFEF. | J95: Art. 151 | K95: ResumenReglamentoCompeticiones.pdf | L95: 1
A96: RC-044 | B96: normativa | C96: Art. 153 | D96: ¿Puede el Presidente del club actuar como delegado según el Artículo 153 del Reglamento de Competiciones? | E96: Sí, es una función habitual que puede asumir el Presidente del club. | F96: No, no puede actuar como delegado el/la Presidente/a o Consejero/a Delegado/a del club. | G96: Sí, siempre que lo autorice expresamente el árbitro antes del partido. | H96: B | I96: El Artículo 153 prohíbe que el Presidente o Consejero Delegado del club actúe como delegado, ni tampoco un miembro de la Junta Directiva de la RFEF. | J96: Art. 153 | K96: ResumenReglamentoCompeticiones.pdf | L96: 2
A97: RC-045 | B97: normativa | C97: Art. 154 | D97: ¿Qué obligación tienen los capitanes respecto al acta, según el Artículo 154 del Reglamento de Competiciones? | E97: Firmar la primera parte del acta antes del comienzo del partido. | F97: Redactar personalmente el informe de incidencias. | G97: No tienen ninguna obligación relacionada con el acta. | H97: A | I97: El Artículo 154 exige que los capitanes firmen la primera parte del acta antes del comienzo del partido. | J97: Art. 154 | K97: ResumenReglamentoCompeticiones.pdf | L97: 2
A98: RC-046 | B98: normativa | C98: Art. 155 | D98: Según el Artículo 155 del Reglamento de Competiciones, ¿cuándo empiezan y terminan las facultades del árbitro? | E98: Empiezan al pitar el inicio y terminan al pitar el final, sin incluir descansos. | F98: Empiezan al entrar en el recinto y no terminan hasta que lo abandona, incluidos descansos y suspensiones. | G98: Solo tiene facultades mientras el balón está en juego. | H98: B | I98: El Artículo 155 establece que las facultades del árbitro empiezan al entrar en el recinto y no terminan hasta que lo abandona, incluyendo descansos y suspensiones. | J98: Art. 155 | K98: ResumenReglamentoCompeticiones.pdf | L98: 3
A99: RC-047 | B99: normativa | C99: Art. 155 | D99: Si el árbitro principal no puede continuar el partido, ¿quién lo sustituye según el Artículo 155 del Reglamento de Competiciones? | E99: El cuarto árbitro automáticamente. | F99: El asistente de superior categoría arbitral. | G99: Se suspende el partido obligatoriamente. | H99: B | I99: El Artículo 155 establece que si el árbitro no puede continuar, lo sustituye el asistente de superior categoría arbitral. | J99: Art. 155 | K99: ResumenReglamentoCompeticiones.pdf | L99: 2
A100: RC-048 | B100: normativa | C100: Art. 156 | D100: Según el Artículo 156 del Reglamento de Competiciones, ¿cuántas personas pueden estar en el terreno de juego sin autorización, sumando futbolistas y equipo arbitral? | E100: 22 futbolistas más árbitros asistentes y 4º árbitro. | F100: 20 futbolistas más árbitros asistentes únicamente. | G100: 24 futbolistas más todo el equipo técnico. | H100: A | I100: El Artículo 156 permite en el terreno de juego a 22 futbolistas más árbitros asistentes y 4º árbitro, sin autorización de nadie más. | J100: Art. 156 | K100: ResumenReglamentoCompeticiones.pdf | L100: 3
A101: RC-049 | B101: normativa | C101: Art. 158 | D101: ¿Con qué antelación mínima debe personarse el equipo arbitral en el campo, según el Artículo 158 del Reglamento de Competiciones? | E101: Una hora. | F101: Hora y media. | G101: Dos horas. | H101: B | I101: El Artículo 158 exige que el equipo arbitral se persone en el campo con una antelación mínima de hora y media. | J101: Art. 158 | K101: ResumenReglamentoCompeticiones.pdf | L101: 1
A102: RC-050 | B102: normativa | C102: Art. 175 | D102: ¿En qué categorías es obligatoria la ambulancia según el Artículo 175 del Reglamento de Competiciones? | E102: Solo en 1ª y 2ª División, sin exigirse en el resto de categorías. | F102: En campos de 1ª/2ª Federación, 1ª/2ª Fed. Femenina y 1ª División de Fútbol Sala. | G102: En todas las categorías sin excepción, incluidas las categorías inferiores. | H102: B | I102: El Artículo 175 exige ambulancia obligatoria en campos de 1ª/2ª Federación, 1ª/2ª Federación Femenina y 1ª División de Fútbol Sala. | J102: Art. 175 | K102: ResumenReglamentoCompeticiones.pdf | L102: 3
A103: RC-051 | B103: normativa | C103: Art. 175 | D103: ¿Qué está prohibido sobre el terreno de juego, marcos/redes de porterías y banderines de córner durante el partido, según el Artículo 175 del Reglamento de Competiciones? | E103: Toda publicidad, sin excepción alguna en esos elementos del terreno de juego. | F103: Únicamente la publicidad de bebidas alcohólicas y tabaco, no el resto. | G103: No hay ninguna restricción publicitaria sobre esos elementos del terreno. | H103: A | I103: El Artículo 175 prohíbe toda publicidad sobre el terreno de juego, marcos/redes de porterías y banderines de córner durante el partido. | J103: Art. 175 | K103: ResumenReglamentoCompeticiones.pdf | L103: 4
A104: RC-052 | B104: normativa | C104: Art. 183 | D104: ¿Qué logotipo es obligatorio en las prendas deportivas fuera de las competiciones profesionales, según el Artículo 183 del Reglamento de Competiciones? | E104: El logotipo de la Liga Profesional. | F104: El logotipo de la RFEF. | G104: No es obligatorio ningún logotipo institucional. | H104: B | I104: El Artículo 183 exige el logotipo de la Liga Profesional en competiciones profesionales y de la RFEF en el resto de categorías. | J104: Art. 183 | K104: ResumenReglamentoCompeticiones.pdf | L104: 3
A105: RC-053 | B105: normativa | C105: Art. 184 | D105: ¿Qué tipo de publicidad está prohibida en las prendas deportivas según el Artículo 184 del Reglamento de Competiciones? | E105: La de bebidas alcohólicas o tabaco. | F105: La de marcas de material deportivo. | G105: La de entidades bancarias. | H105: A | I105: El Artículo 184 prohíbe anunciar bebidas alcohólicas o tabaco, y prohíbe alterar los colores o emblemas del club. | J105: Art. 184 | K105: ResumenReglamentoCompeticiones.pdf | L105: 1
A106: RC-054 | B106: normativa | C106: Art. 185 | D106: ¿A partir de qué tamaño se considera publicidad la marca del fabricante de la prenda, según el Artículo 185 del Reglamento de Competiciones? | E106: A partir de 10 cm². | F106: A partir de 15 cm². | G106: A partir de 20 cm². | H106: B | I106: El Artículo 185 establece que no se considera publicidad la marca del fabricante si no excede 15 cm² en conjunto. | J106: Art. 185 | K106: ResumenReglamentoCompeticiones.pdf | L106: 2
... A232: RC-196 | B232: normativa | C232: Art. 133 | D232: Según el Artículo 133 del Reglamento de Competiciones, ¿a partir de qué momento se considera a un equipo no comparecido? | E232: Si transcurren 30 minutos desde la hora fijada sin presentarse o con jugadores insuficientes. | F232: Si transcurren 15 minutos desde la hora fijada sin presentarse. | G232: Si transcurre 1 hora desde la hora fijada sin presentarse. | H232: A | I232: El Artículo 133 considera no comparecido a un equipo si transcurren 30 minutos desde la hora fijada sin presentarse o con jugadores insuficientes. | J232: Art. 133 | K232: ResumenReglamentoCompeticiones.pdf | L232: 2
A233: RJ1-001 | B233: reglas | C233: Regla 1 | D233: Durante un partido en el que se utiliza el VAR, un miembro del cuerpo técnico intenta comunicarse por radio con el AVAR sin estar autorizado para ello. ¿Qué establece la Regla 1 al respecto? | E233: Que solo las personas autorizadas podrán entrar en la sala de vídeo o comunicarse con el VAR, el AVAR o el técnico de repeticiones. | F233: Que solo las personas autorizadas podrán entrar en la sala de vídeo, pudiendo comunicarse con el VAR, el AVAR o el técnico de repeticiones los miembros del cuerpo técnico. | G233: Que solo las personas autorizadas podrán comunicarse con el VAR, el AVAR o el técnico de repeticiones, pudiendo entrar en la sala de vídeo los miembros del cuerpo técnico. | H233: A | I233: Durante el partido, únicamente las personas autorizadas podrán entrar en la sala de vídeo o comunicarse con el VAR, el AVAR o el técnico de repeticiones. | J233: Regla 1 / Árbitros asistentes de vídeo (VAR) | K233: ReglasDelJuego26-27.pdf | L233: 2 | M233: 29
A234: RJ1-002 | B234: reglas | C234: Regla 1 | D234: ¿Qué establece la Regla 1 sobre el cumplimiento de un programa de calidad para las porterías empleadas en competiciones oficiales auspiciadas por la FIFA o las confederaciones? | E234: Se recomienda que cumplan los criterios del Programa de calidad de la FIFA de porterías de fútbol. | F234: Es obligatorio que cumplan los criterios del Programa de calidad de la FIFA de porterías de fútbol. | G234: No existe ninguna referencia normativa sobre programas de calidad para las porterías. | H234: A | I234: La Regla 1 recomienda, sin imponerlo como obligación, que las porterías empleadas en competiciones oficiales auspiciadas por la FIFA o las confederaciones cumplan los criterios del Programa de calidad de la FIFA de porterías de fútbol. | J234: Regla 1 / Porterías | K234: ReglasDelJuego26-27.pdf | L234: 2 | M234: 27
A235: RJ1-003 | B235: reglas | C235: Regla 1 | D235: ¿Cómo describe la Regla 1 la composición de una portería respecto a los postes de los banderines de esquina? | E235: Dos postes verticales equidistantes de los postes de los banderines de esquina, unidos por un travesaño horizontal. | F235: Dos postes verticales situados a la misma distancia entre sí que los postes de los banderines de esquina. | G235: Dos postes verticales alineados con los postes de los banderines de esquina, sin travesaño obligatorio. | H235: A | I235: Una portería consta de dos postes verticales, equidistantes de los postes de los banderines de esquina y unidos en la parte superior por un travesaño horizontal. | J235: Regla 1 / Porterías | K235: ReglasDelJuego26-27.pdf | L235: 2 | M235: 27
A236: RJ1-004 | B236: reglas | C236: Regla 1 | D236: Un club fabrica los postes de su portería con un material no homologado que, además, resulta peligroso para los jugadores. ¿Qué exige la Regla 1 sobre los materiales de postes y travesaño? | E236: Que estén fabricados con materiales homologados y no constituyan ningún peligro. | F236: Que estén fabricados con materiales homologados, aunque puedan suponer cierto riesgo si el club lo asume. | G236: Que el material sea decidido libremente por el club, sin exigencia de homologación. | H236: A | I236: Los postes y el travesaño deberán estar fabricados con materiales homologados y no deberán constituir ningún peligro. | J236: Regla 1 / Porterías | K236: ReglasDelJuego26-27.pdf | L236: 2 | M236: 27
A237: RJ1-005 | B237: reglas | C237: Regla 1 | D237: ¿En qué momento debe el árbitro comprobar el correcto funcionamiento de la DAG, según la Regla 1? | E237: Antes del partido, según lo estipulado en el manual de pruebas. | F237: Antes del partido, salvo que el árbitro lo considere innecesario, según lo estipulado en el manual de pruebas. | G237: Durante el descanso, antes de iniciar la segunda parte, según lo estipulado en el manual de pruebas. | H237: A | I237: Cuando se vaya a hacer uso de la DAG, el árbitro deberá comprobar su correcto funcionamiento antes del partido, según se estipula en el manual de pruebas. | J237: Regla 1 / Detección automática de goles | K237: ReglasDelJuego26-27.pdf | L237: 2 | M237: 29
A238: RJ1-006 | B238: reglas | C238: Regla 1 | D238: Si se utiliza la DAG en competición, ¿a qué deben extenderse las garantías exigidas a los organizadores sobre el cumplimiento del Programa de calidad de la FIFA? | E238: Al sistema completo, incluidos los posibles cambios autorizados en los marcos de las porterías o en la tecnología usada en los balones. | F238: Al dispositivo instalado en la línea de meta, incluidos los posibles cambios autorizados en los marcos de las porterías, pero no a la tecnología usada en los balones. | G238: Al sistema completo, excluidos los posibles cambios autorizados en los marcos de las porterías o en la tecnología usada en los balones. | H238: A | I238: Los organizadores deberán garantizar que el sistema, incluidos los posibles cambios autorizados en los marcos de las porterías o en la tecnología usada en los balones, cumpla con los requisitos del Programa de calidad de la FIFA. | J238: Regla 1 / Detección automática de goles | K238: ReglasDelJuego26-27.pdf | L238: 3 | M238: 29
A239: RJ1-007 | B239: reglas | C239: Regla 1 | D239: ¿Hasta cuándo se prohíbe la publicidad comercial en el terreno de juego una vez finalizado el descanso, según la Regla 1? | E239: Desde que los equipos vuelven a entrar en el terreno de juego hasta el término del partido. | F239: Desde que los equipos vuelven a entrar en el terreno de juego hasta que se reanuda el juego. | G239: Desde que se reanuda el juego tras el descanso hasta el término del partido. | H239: A | I239: La prohibición de publicidad rige también desde el momento en que los equipos vuelven a entrar en el terreno de juego hasta el término del partido. | J239: Regla 1 / Publicidad comercial | K239: ReglasDelJuego26-27.pdf | L239: 2 | M239: 29
A240: RJ1-008 | B240: reglas | C240: Regla 1 | D240: ¿A qué tipo de partidos se relaciona particularmente el área técnica, según la Regla 1? | E240: A los disputados en estadios que cuentan con un área específica con asientos para el cuerpo técnico, los suplentes y los jugadores sustituidos. | F240: A los disputados en estadios que cuentan con un área específica con asientos para el cuerpo técnico y los suplentes, con exclusión de los jugadores sustituidos. | G240: A los disputados en competiciones internacionales organizadas por la FIFA en estadios que cuentan con un área específica con asientos. | H240: A | I240: El área técnica se relaciona en particular con los partidos disputados en estadios que cuentan con un área específica con asientos para el cuerpo técnico, los suplentes y los jugadores sustituidos. | J240: Regla 1 / Área técnica | K240: ReglasDelJuego26-27.pdf | L240: 2 | M240: 27
A241: RJ1-010 | B241: reglas | C241: Regla 1 | D241: Un club solicita disputar sus partidos sobre una superficie completamente artificial. ¿Es posible según la Regla 1? | E241: Sí, siempre que lo permita el reglamento de la competición. | F241: No, la superficie completamente artificial solo se permite si lo autoriza la FIFA para cada partido. | G241: Sí, siempre que lo permita el árbitro antes del inicio de cada partido. | H241: A | I241: La Regla 1 permite una superficie completamente artificial si lo autoriza el reglamento de la competición. | J241: Regla 1 / Superficie de juego | K241: ReglasDelJuego26-27.pdf | L241: 1 | M241: 25
A242: RJ1-011 | B242: reglas | C242: Regla 1 | D242: Un campo combina césped natural con fibras artificiales integradas en el mismo terreno. ¿Qué condición exige la Regla 1 para que este sistema híbrido sea válido? | E242: Que el reglamento de la competición lo permita expresamente. | F242: Que lo autorice el árbitro antes de cada partido concreto. | G242: Que el club lo comunique a la federación con 15 días de antelación. | H242: A | I242: La combinación integrada de materiales artificiales y naturales (sistema híbrido) requiere que el reglamento de la competición lo permita. | J242: Regla 1 / Superficie de juego | K242: ReglasDelJuego26-27.pdf | L242: 3 | M242: 25
A243: RJ1-013 | B243: reglas | C243: Regla 1 | D243: En partidos internacionales de competición de clubes disputados sobre superficie artificial, ¿qué debe cumplir dicha superficie según la Regla 1? | E243: Los requisitos del Programa de calidad de la FIFA de césped artificial, salvo dispensa especial del IFAB. | F243: Los requisitos del Programa de calidad de la FIFA de césped artificial, salvo dispensa especial de la federación anfitriona. | G243: Los requisitos que determine la federación anfitriona del partido, salvo dispensa especial del IFAB. | H243: A | I243: Las superficies artificiales en partidos internacionales de clubes deben cumplir el Programa de calidad de la FIFA de césped artificial, salvo dispensa del IFAB. | J243: Regla 1 / Superficie de juego | K243: ReglasDelJuego26-27.pdf | L243: 3 | M243: 25
A244: RJ1-016 | B244: reglas | C244: Regla 1 | D244: En una superficie artificial coexisten las líneas de demarcación de fútbol con las de otro deporte. ¿Qué exige la Regla 1 para que esto sea admisible? | E244: Que las líneas del otro deporte sean de un color diferente y se distingan claramente de las de fútbol. | F244: Que las líneas del otro deporte se borren antes de cada partido de fútbol. | G244: Que ambos deportes utilicen exactamente el mismo grosor de línea para evitar confusión. | H244: A | I244: En superficies artificiales se permite la coexistencia con otras líneas siempre que sean de color diferente y se distingan claramente de las de fútbol. | J244: Regla 1 / Marcación del terreno | K244: ReglasDelJuego26-27.pdf | L244: 3 | M244: 25
...

Sheet Resumen Reglas
A1: Regla / Tema | B1: Nº preguntas
A2: Regla 1 | B2: =COUNTIF('Banco de preguntas'!$C:$C,"Regla 1") -> 97
A3: Regla 2 | B3: =COUNTIF('Banco de preguntas'!$C:$C,"Regla 2") -> 32
A4: Regla 3 | B4: =COUNTIF('Banco de preguntas'!$C:$C,"Regla 3") -> 88
A5: Regla 4 | B5: =COUNTIF('Banco de preguntas'!$C:$C,"Regla 4") -> 77
A6: Regla 5 | B6: =COUNTIF('Banco de preguntas'!$C:$C,"Regla 5") -> 81
A7: Regla 6 | B7: =COUNTIF('Banco de preguntas'!$C:$C,"Regla 6") -> 48
A8: Regla 7 | B8: =COUNTIF('Banco de preguntas'!$C:$C,"Regla 7") -> 38
A9: Regla 8 | B9: =COUNTIF('Banco de preguntas'!$C:$C,"Regla 8") -> 39
A10: Regla 9 | B10: =COUNTIF('Banco de preguntas'!$C:$C,"Regla 9") -> 30
A11: Regla 10 | B11: =COUNTIF('Banco de preguntas'!$C:$C,"Regla 10") -> 51
A12: Regla 11 | B12: =COUNTIF('Banco de preguntas'!$C:$C,"Regla 11") -> 61
A13: Regla 12 | B13: =COUNTIF('Banco de preguntas'!$C:$C,"Regla 12") -> 202
A14: Regla 13 | B14: =COUNTIF('Banco de preguntas'!$C:$C,"Regla 13") -> 45
A15: Regla 14 | B15: =COUNTIF('Banco de preguntas'!$C:$C,"Regla 14") -> 56
A16: Regla 15 | B16: =COUNTIF('Banco de preguntas'!$C:$C,"Regla 15") -> 42
A17: Regla 16 | B17: =COUNTIF('Banco de preguntas'!$C:$C,"Regla 16") -> 28
A18: Regla 17 | B18: =COUNTIF('Banco de preguntas'!$C:$C,"Regla 17") -> 24
A19: Glosario | B19: =COUNTIF('Banco de preguntas'!$C:$C,"Glosario") -> 63
A20: VAR | B20: =COUNTIF('Banco de preguntas'!$C:$C,"VAR")+COUNTIF('Banco de preguntas'!$C:$C,"Protocolo del VAR") -> 57
A21: Normativa (Reglamento y Bases) | B21: =COUNTIF('Banco de preguntas'!$B:$B,"normativa") -> 231
A22: TOTAL | B22: =SUM(B2:B21) -> 1390

Sheet Regla 1
A1: ID | B1: Tipo | C1: Enunciado | D1: Opción A | E1: Opción B | F1: Opción C | G1: Correcta | H1: Explicación | I1: Referencia | J1: Dificultad
A2: RJ1-001 | B2: situacion | C2: Durante un partido en el que se utiliza el VAR, un miembro del cuerpo técnico intenta comunicarse por radio con el AVAR sin estar autorizado para ello. ¿Qué establece la Regla 1 al respecto? | D2: Que solo las personas autorizadas podrán entrar en la sala de vídeo o comunicarse con el VAR, el AVAR o el técnico de repeticiones. | E2: Que solo las personas autorizadas podrán entrar en la sala de vídeo, pudiendo comunicarse con el VAR, el AVAR o el técnico de repeticiones los miembros del cuerpo técnico. | F2: Que solo las personas autorizadas podrán comunicarse con el VAR, el AVAR o el técnico de repeticiones, pudiendo entrar en la sala de vídeo los miembros del cuerpo técnico. | G2: A | H2: Durante el partido, únicamente las personas autorizadas podrán entrar en la sala de vídeo o comunicarse con el VAR, el AVAR o el técnico de repeticiones. | I2: Regla 1 / Árbitros asistentes de vídeo (VAR) | J2: 2
A3: RJ1-002 | B3: directa | C3: ¿Qué establece la Regla 1 sobre el cumplimiento de un programa de calidad para las porterías empleadas en competiciones oficiales auspiciadas por la FIFA o las confederaciones? | D3: Se recomienda que cumplan los criterios del Programa de calidad de la FIFA de porterías de fútbol. | E3: Es obligatorio que cumplan los criterios del Programa de calidad de la FIFA de porterías de fútbol. | F3: No existe ninguna referencia normativa sobre programas de calidad para las porterías. | G3: A | H3: La Regla 1 recomienda, sin imponerlo como obligación, que las porterías empleadas en competiciones oficiales auspiciadas por la FIFA o las confederaciones cumplan los criterios del Programa de calidad de la FIFA de porterías de fútbol. | I3: Regla 1 / Porterías | J3: 2
A4: RJ1-003 | B4: directa | C4: ¿Cómo describe la Regla 1 la composición de una portería respecto a los postes de los banderines de esquina? | D4: Dos postes verticales equidistantes de los postes de los banderines de esquina, unidos por un travesaño horizontal. | E4: Dos postes verticales situados a la misma distancia entre sí que los postes de los banderines de esquina. | F4: Dos postes verticales alineados con los postes de los banderines de esquina, sin travesaño obligatorio. | G4: A | H4: Una portería consta de dos postes verticales, equidistantes de los postes de los banderines de esquina y unidos en la parte superior por un travesaño horizontal. | I4: Regla 1 / Porterías | J4: 2
A5: RJ1-004 | B5: situacion | C5: Un club fabrica los postes de su portería con un material no homologado que, además, resulta peligroso para los jugadores. ¿Qué exige la Regla 1 sobre los materiales de postes y travesaño? | D5: Que estén fabricados con materiales homologados y no constituyan ningún peligro. | E5: Que estén fabricados con materiales homologados, aunque puedan suponer cierto riesgo si el club lo asume. | F5: Que el material sea decidido libremente por el club, sin exigencia de homologación. | G5: A | H5: Los postes y el travesaño deberán estar fabricados con materiales homologados y no deberán constituir ningún peligro. | I5: Regla 1 / Porterías | J5: 2
A6: RJ1-005 | B6: directa | C6: ¿En qué momento debe el árbitro comprobar el correcto funcionamiento de la DAG, según la Regla 1? | D6: Antes del partido, según lo estipulado en el manual de pruebas. | E6: Antes del partido, salvo que el árbitro lo considere innecesario, según lo estipulado en el manual de pruebas. | F6: Durante el descanso, antes de iniciar la segunda parte, según lo estipulado en el manual de pruebas. | G6: A | H6: Cuando se vaya a hacer uso de la DAG, el árbitro deberá comprobar su correcto funcionamiento antes del partido, según se estipula en el manual de pruebas. | I6: Regla 1 / Detección automática de goles | J6: 2
A7: RJ1-006 | B7: situacion | C7: Si se utiliza la DAG en competición, ¿a qué deben extenderse las garantías exigidas a los organizadores sobre el cumplimiento del Programa de calidad de la FIFA? | D7: Al sistema completo, incluidos los posibles cambios autorizados en los marcos de las porterías o en la tecnología usada en los balones. | E7: Al dispositivo instalado en la línea de meta, incluidos los posibles cambios autorizados en los marcos de las porterías, pero no a la tecnología usada en los balones. | F7: Al sistema completo, excluidos los posibles cambios autorizados en los marcos de las porterías o en la tecnología usada en los balones. | G7: A | H7: Los organizadores deberán garantizar que el sistema, incluidos los posibles cambios autorizados en los marcos de las porterías o en la tecnología usada en los balones, cumpla con los requisitos del Programa de calidad de la FIFA. | I7: Regla 1 / Detección automática de goles | J7: 3
A8: RJ1-007 | B8: directa | C8: ¿Hasta cuándo se prohíbe la publicidad comercial en el terreno de juego una vez finalizado el descanso, según la Regla 1? | D8: Desde que los equipos vuelven a entrar en el terreno de juego hasta el término del partido. | E8: Desde que los equipos vuelven a entrar en el terreno de juego hasta que se reanuda el juego. | F8: Desde que se reanuda el juego tras el descanso hasta el término del partido. | G8: A | H8: La prohibición de publicidad rige también desde el momento en que los equipos vuelven a entrar en el terreno de juego hasta el término del partido. | I8: Regla 1 / Publicidad comercial | J8: 2
A9: RJ1-008 | B9: directa | C9: ¿A qué tipo de partidos se relaciona particularmente el área técnica, según la Regla 1? | D9: A los disputados en estadios que cuentan con un área específica con asientos para el cuerpo técnico, los suplentes y los jugadores sustituidos. | E9: A los disputados en estadios que cuentan con un área específica con asientos para el cuerpo técnico y los suplentes, con exclusión de los jugadores sustituidos. | F9: A los disputados en competiciones internacionales organizadas por la FIFA en estadios que cuentan con un área específica con asientos. | G9: A | H9: El área técnica se relaciona en particular con los partidos disputados en estadios que cuentan con un área específica con asientos para el cuerpo técnico, los suplentes y los jugadores sustituidos. | I9: Regla 1 / Área técnica | J9: 2
A10: RJ1-010 | B10: situacion | C10: Un club solicita disputar sus partidos sobre una superficie completamente artificial. ¿Es posible según la Regla 1? | D10: Sí, siempre que lo permita el reglamento de la competición. | E10: No, la superficie completamente artificial solo se permite si lo autoriza la FIFA para cada partido. | F10: Sí, siempre que lo permita el árbitro antes del inicio de cada partido. | G10: A | H10: La Regla 1 permite una superficie completamente artificial si lo autoriza el reglamento de la competición. | I10: Regla 1 / Superficie de juego | J10: 1
A11: RJ1-011 | B11: situacion | C11: Un campo combina césped natural con fibras artificiales integradas en el mismo terreno. ¿Qué condición exige la Regla 1 para que este sistema híbrido sea válido? | D11: Que el reglamento de la competición lo permita expresamente. | E11: Que lo autorice el árbitro antes de cada partido concreto. | F11: Que el club lo comunique a la federación con 15 días de antelación. | G11: A | H11: La combinación integrada de materiales artificiales y naturales (sistema híbrido) requiere que el reglamento de la competición lo permita. | I11: Regla 1 / Superficie de juego | J11: 3
A12: RJ1-013 | B12: situacion | C12: En partidos internacionales de competición de clubes disputados sobre superficie artificial, ¿qué debe cumplir dicha superficie según la Regla 1? | D12: Los requisitos del Programa de calidad de la FIFA de césped artificial, salvo dispensa especial del IFAB. | E12: Los requisitos del Programa de calidad de la FIFA de césped artificial, salvo dispensa especial de la federación anfitriona. | F12: Los requisitos que determine la federación anfitriona del partido, salvo dispensa especial del IFAB. | G12: A | H12: Las superficies artificiales en partidos internacionales de clubes deben cumplir el Programa de calidad de la FIFA de césped artificial, salvo dispensa del IFAB. | I12: Regla 1 / Superficie de juego | J12: 3
A13: RJ1-016 | B13: situacion | C13: En una superficie artificial coexisten las líneas de demarcación de fútbol con las de otro deporte. ¿Qué exige la Regla 1 para que esto sea admisible? | D13: Que las líneas del otro deporte sean de un color diferente y se distingan claramente de las de fútbol. | E13: Que las líneas del otro deporte se borren antes de cada partido de fútbol. | F13: Que ambos deportes utilicen exactamente el mismo grosor de línea para evitar confusión. | G13: A | H13: En superficies artificiales se permite la coexistencia con otras líneas siempre que sean de color diferente y se distingan claramente de las de fútbol. | I13: Regla 1 / Marcación del terreno | J13: 3
... A98: RJ1-114 | B98: situacion | C98: Un terreno de juego cuenta con césped híbrido, que combina fibras naturales y artificiales entrelazadas. ¿Se ajusta esto a lo que permite la Regla 1 sobre el tipo de superficie? | D98: Sí, el terreno de juego puede ser de césped natural, artificial o una combinación de ambos, lo que incluye sistemas híbridos, siempre que lo permita el reglamento de la competición. | E98: No, un sistema híbrido no está contemplado entre los tipos de superficie que permite la Regla 1, que solo admite césped natural o artificial de forma independiente. | F98: Sí, sin que sea necesaria ninguna autorización del reglamento de la competición para este tipo concreto de superficie. | G98: A | H98: La Regla 1 permite que el terreno de juego sea de césped natural, artificial o una combinación de ambos (lo que incluye los sistemas híbridos), siempre que lo permita el reglamento de la competición. | I98: Regla 1 | J98: 3

Sheet Regla 2
A1: ID | B1: Tipo | C1: Enunciado | D1: Opción A | E1: Opción B | F1: Opción C | G1: Correcta | H1: Explicación | I1: Referencia | J1: Dificultad
A2: RJ2-001 | B2: directa | C2: ¿Pueden los capitanes proponer al árbitro el cambio de balón durante el transcurso del juego? | D2: Sí, pero será potestad del árbitro atender o no la petición. | E2: Sí, y el árbitro está obligado a comprobarlo y cambiarlo. | F2: No, el balón solo puede cambiarse por iniciativa del árbitro. | G2: A | H2: Los capitanes pueden proponer el cambio de balón, pero corresponde al árbitro decidir si atiende o no dicha petición. | I2: Regla 2 | J2: 1
A3: RJ2-003 | B3: directa | C3: ¿Cuál es la circunferencia reglamentaria del balón? | D3: Entre 68 y 70 cm. | E3: Entre 64 y 66 cm. | F3: Entre 70 y 72 cm. | G3: A | H3: La circunferencia del balón debe estar comprendida entre 68 y 70 cm. | I3: Regla 2 / Características y medidas | J3: 1
A4: RJ2-004 | B4: directa | C4: ¿Cuál es el peso reglamentario del balón al comienzo del partido? | D4: Entre 410 y 450 g. | E4: Entre 400 y 440 g. | F4: Entre 420 y 460 g. | G4: A | H4: El balón debe tener un peso comprendido entre 410 y 450 g al comienzo del partido. | I4: Regla 2 / Características y medidas | J4: 1
A5: RJ2-005 | B5: directa | C5: ¿Cuál es la presión reglamentaria del balón al nivel del mar? | D5: Entre 0,6 y 1,1 atmósferas. | E5: Entre 0,4 y 0,9 atmósferas. | F5: Entre 1,0 y 1,5 atmósferas. | G5: A | H5: La presión del balón debe ser equivalente a 0,6–1,1 atmósferas al nivel del mar. | I5: Regla 2 / Características y medidas | J5: 2
A6: RJ2-006 | B6: situacion | C6: Un delegado presenta un balón cuyo peso al inicio del partido es de 405 g, dentro de una circunferencia de 69 cm. ¿Es reglamentario? | D6: No, porque el peso no alcanza el mínimo de 410 g exigido al comienzo del partido. | E6: Sí, porque el peso solo se exige a partir de la segunda parte del encuentro. | F6: Sí, porque la circunferencia está dentro del rango permitido y basta con ello. | G6: A | H6: El balón debe pesar entre 410 y 450 g al comienzo del partido; con 405 g queda por debajo del mínimo exigido. | I6: Regla 2 / Características y medidas | J6: 3
A7: RJ2-007 | B7: situacion | C7: En partidos de competición oficial organizados bajo los auspicios de la FIFA o las confederaciones, ¿qué deben cumplir los balones utilizados? | D7: Los criterios del Programa de calidad de la FIFA de balones de fútbol y portar uno de sus sellos de calidad. | E7: Los criterios del Programa de calidad de la FIFA de balones de fútbol, sin necesidad de portar ningún sello de calidad. | F7: Los criterios que fije cada federación nacional de fútbol y portar uno de sus sellos de calidad. | G7: A | H7: Todos los balones utilizados en partidos de competición oficial de la FIFA o confederaciones deben cumplir los criterios del Programa de calidad de la FIFA de balones de fútbol y portar uno de sus sellos de calidad. | I7: Regla 2 / Características y medidas | J7: 3
A8: RJ2-008 | B8: directa | C8: ¿Qué indican los distintivos o sellos de calidad que puede portar un balón? | D8: Que el balón ha sido examinado oficialmente y cumple los requisitos técnicos mínimos estipulados en la Regla 2. | E8: Que el balón ha sido examinado oficialmente y cumple los requisitos técnicos máximos estipulados en la Regla 2. | F8: Que el balón ha sido fabricado en un país autorizado por la FIFA y cumple los requisitos técnicos mínimos de la Regla 2. | G8: A | H8: Estos distintivos indican que el balón ha sido examinado oficialmente y cumple los requisitos técnicos mínimos estipulados en la Regla 2 y aprobados por el IFAB. | I8: Regla 2 / Características y medidas | J8: 3
A9: RJ2-009 | B9: directa | C9: ¿Pueden las federaciones nacionales de fútbol exigir en sus competiciones el uso de balones con sello de calidad? | D9: Sí, en las competiciones de las federaciones nacionales se podrá exigir el uso de balones que lleven uno de estos distintivos. | E9: No, esa exigencia está reservada a la FIFA y a las confederaciones continentales de fútbol. | F9: Sí, en las competiciones de las federaciones nacionales de categorías profesionales masculinas de máximo nivel. | G9: A | H9: En las competiciones de las federaciones nacionales de fútbol, se podrá exigir el uso de balones que lleven uno de estos distintivos de calidad. | I9: Regla 2 / Características y medidas | J9: 2
A10: RJ2-010 | B10: situacion | C10: En un partido de competición oficial bajo los auspicios de una federación nacional, ¿qué publicidad comercial está permitida en el balón? | D10: El logotipo o emblema de la competición o su organizador, y la marca registrada autorizada del fabricante. | E10: El logotipo o emblema de la competición o su organizador, y el de los patrocinadores del club local. | F10: El logotipo o emblema de la federación nacional, y la marca registrada autorizada del fabricante. | G10: A | H10: Está prohibida toda publicidad comercial en el balón, con excepción del logotipo o emblema de la competición o su organizador y la marca registrada autorizada del fabricante. | I10: Regla 2 / Características y medidas | J10: 3
A11: RJ2-011 | B11: directa | C11: ¿Quién puede restringir el tamaño y el número de las marcas autorizadas del fabricante en el balón? | D11: El reglamento de la competición. | E11: El fabricante del balón. | F11: El árbitro principal, antes del inicio de cada partido. | G11: A | H11: El reglamento de la competición podrá restringir el tamaño y el número de dichas marcas. | I11: Regla 2 / Características y medidas | J11: 2
A12: RJ2-012 | B12: situacion | C12: Durante el juego habitual, el balón pierde sus propiedades y no puede seguir utilizándose. ¿Qué debe hacer el árbitro? | D12: Detener el juego y reanudarlo con un balón a tierra. | E12: Detener el juego y reanudarlo con un saque de banda a favor del equipo que tenía la posesión. | F12: Permitir que el juego continúe hasta la siguiente interrupción natural. | G12: A | H12: Si el balón perdiera sus propiedades y no pudiera seguir utilizándose, se detendrá el juego y se reanudará con un balón a tierra. | I12: Regla 2 / Sustitución de un balón defectuoso | J12: 1
A13: RJ2-015 | B13: situacion | C13: Durante la ejecución de un tiro penal, el balón queda defectuoso mientras se desplaza hacia adelante, antes de tocar a ningún jugador, el poste o el travesaño, y el guardameta llega a detenerlo. ¿Qué decisión toma el árbitro? | D13: Ordena repetir el lanzamiento. | E13: Concede un balón a tierra al guardameta. | F13: Concede un saque de meta. | G13: A | H13: Si el balón queda defectuoso en el lanzamiento de un tiro penal (o de la tanda de penales) mientras se desplaza hacia adelante, antes de tocar a un jugador, el poste o el travesaño, se vuelve a ejecutar el lanzamiento, con independencia de que el guardameta lo detenga. | I13: Regla 2 / Sustitución de un balón defectuoso | J13: 3
... A33: RJ2-045 | B33: situacion | C33: En una competición no organizada bajo los auspicios de la FIFA ni de las confederaciones, un club presenta un balón sin sello de calidad que cumple las especificaciones de la Regla 2. ¿Puede utilizarse? | D33: Sí, salvo que el reglamento de esa competición exija el sello de calidad. | E33: No, todo balón de competición oficial debe llevar un sello de calidad. | F33: No, sin sello de calidad el balón se considera defectuoso. | G33: A | H33: Portar uno de los sellos de calidad no es una exigencia general para cualquier balón; solo se exige obligatoriamente en las competiciones oficiales de la FIFA o las confederaciones, y de forma potestativa en las de las federaciones nacionales que así lo decidan. | I33: Regla 2 | J33: 3

Sheet Regla 3
A1: ID | B1: Tipo | C1: Enunciado | D1: Opción A | E1: Opción B | F1: Opción C | G1: Correcta | H1: Explicación | I1: Referencia | J1: Dificultad
A2: RJ3-001 | B2: situacion | C2: Un suplente entra en el terreno de juego sin permiso del árbitro y marca un gol; el árbitro se da cuenta antes de que se reanude el juego. El árbitro... | D2: Anula el gol, amonesta al suplente y reanuda con tiro libre directo en el lugar de la interferencia. | E2: Anula el gol, amonesta al suplente y reanuda con tiro libre directo desde el área de meta. | F2: Anula el gol, amonesta al suplente y reanuda con balón a tierra desde el área de meta. | G2: A | H2: Entrar al terreno de juego sin autorización del árbitro se sanciona con amonestación, anulación del gol si procede, y tiro libre directo a favor del equipo defensor desde el lugar donde se produjo la interferencia. | I2: Regla 3 | J2: 4
A3: RJ3-002 | B3: situacion | C3: Un jugador que va a ser sustituido se niega a abandonar el terreno de juego. El árbitro... | D3: Lo amonesta por conducta antideportiva. | E3: Lo amonesta por retrasar la reanudación del juego. | F3: No toma medida disciplinaria y el partido continúa. | G3: C | H3: Regla 3 (pág. 34): «si un jugador que debe ser sustituido se negara a salir del terreno de juego, el partido continuará». | I3: Regla 3 | J3: 2
A4: RJ3-003 | B4: situacion | C4: El preparador físico, situado en la zona de calentamiento, detiene el balón antes de que salga del campo, sin intención de interferir en el juego. ¿Qué decisión toma el árbitro? | D4: Tiro libre directo o penal a favor del equipo contrario, y expulsión del preparador físico. | E4: Tiro libre indirecto en el lugar de la infracción, sin amonestación. | F4: Tiro libre directo o penal a favor del equipo contrario, y amonestación al preparador físico por entrar al terreno de juego sin permiso. | G4: B | H4: Detener el balón sin intención de interferir, desde fuera del terreno, se sanciona con tiro libre indirecto en el lugar de la infracción, sin sanción disciplinaria si no hubo intención de interferir. | I4: Regla 3 / Regla 12 | J4: 4
A5: RJ3-004 | B5: situacion | C5: Un equipo presenta solo nueve jugadores nombrados en el saque inicial. ¿Pueden incorporarse al partido los dos jugadores que faltaban una vez comenzado? | D5: Sí, siempre que el árbitro conociera sus nombres antes del comienzo y las reglas de la competición lo permitan. | E5: No, deben estar presentes antes del comienzo del encuentro, sin excepción prevista en las Reglas de Juego. | F5: Sí, siempre que el árbitro conociera sus nombres antes del comienzo, aunque las reglas de la competición no lo permitan. | G5: A | H5: Los jugadores pueden incorporarse una vez comenzado el partido si el árbitro conocía sus nombres previamente y el reglamento de la competición lo permite. | I5: Regla 3 | J5: 3
A6: RJ3-005 | B6: situacion | C6: Un jugador incluido en la lista del equipo es expulsado mientras realiza el calentamiento, 20 minutos antes del comienzo del partido. ¿Qué ocurre? | D6: El equipo empieza el partido con un jugador menos. | E6: No se puede expulsar a ningún jugador antes del saque inicial. | F6: En su lugar juega un suplente, y no se cuenta como sustitución. | G6: C | H6: Si la expulsión se produce antes del inicio del partido, el jugador expulsado puede ser reemplazado por un suplente sin que compute como sustitución. | I6: Regla 3 | J6: 3
A7: RJ3-006 | B7: situacion | C7: Un suplente que está calentando detrás de la portería entra al terreno de juego e impide con el pie una oportunidad manifiesta de gol. ¿Qué decisión toma el árbitro? | D7: Lo amonesta y reanuda con tiro libre directo o penal. | E7: Lo expulsa y reanuda con tiro libre directo o penal. | F7: Lo expulsa y reanuda con tiro libre indirecto. | G7: B | H7: Impedir una ocasión manifiesta de gol mediante la entrada ilegal de un suplente se sanciona con expulsión y tiro libre directo o penal según el lugar de la infracción. | I7: Regla 3 / Regla 12 | J7: 2
A8: RJ3-007 | B8: directa | C8: ¿Puede comenzar un partido un equipo con menos de 7 jugadores? | D8: No, el partido no puede comenzar con menos de 7 jugadores. | E8: Sí, si lo permite el reglamento de la competición. | F8: Sí, en partidos amistosos. | G8: A | H8: La Regla 3 exige un mínimo de 7 jugadores por equipo para poder comenzar el partido, sin excepciones por tipo de competición. | I8: Regla 3 | J8: 1
A9: RJ3-008 | B9: situacion | C9: Un guardameta y un jugador de campo intercambian su puesto sin avisar al árbitro. ¿Qué decisión toma el árbitro? | D9: Permite que el juego continúe y apercibe verbalmente a ambos cuando el balón deje de estar en juego. | E9: Permite que el juego continúe y amonesta a ambos cuando el balón deje de estar en juego. | F9: Detiene el juego, reanuda con tiro libre indirecto y amonesta a ambos por el cambio no autorizado. | G9: B | H9: El intercambio de puesto entre guardameta y jugador de campo sin autorización se sanciona, en la siguiente interrupción, con amonestación a ambos jugadores, sin necesidad de detener el juego en el momento. | I9: Regla 3 | J9: 3
A10: RJ3-009 | B10: directa | C10: ¿Cuál es el número mínimo de futbolistas necesario, según la Regla 3, para que un equipo pueda continuar un partido ya iniciado sin darlo por finalizado? | D10: 6 jugadores. | E10: 7 jugadores. | F10: 8 jugadores. | G10: B | H10: El mínimo de 7 jugadores exigido para iniciar un partido es también el umbral por debajo del cual el partido no puede continuar. | I10: Regla 3 | J10: 2
A11: RJ3-010 | B11: situacion | C11: El árbitro inspecciona el equipamiento del suplente a la altura de la línea de medio campo antes de permitir una sustitución. ¿Cuándo empieza a contar el plazo de diez segundos del sustituido? | D11: Cuando la inspección haya terminado y el árbitro indique que se efectúe la sustitución. | E11: Cuando el árbitro comienza a inspeccionar el equipamiento del suplente. | F11: Cuando el cuarto árbitro muestra el tablero, aunque la inspección no haya concluido. | G11: A | H11: Según el protocolo del límite de tiempo en las sustituciones, si el árbitro inspecciona el equipamiento del suplente en la línea de medio campo, los diez segundos empiezan cuando la inspección ha terminado y el árbitro indica que se efectúe la sustitución. | I11: Regla 3.3 / Procedimiento de sustitución | J11: 3
A12: RJ3-011 | B12: situacion | C12: Un jugador sustituido se encuentra muy cerca de la línea de banda, cruzándola, cuando el árbitro termina la cuenta atrás de cinco segundos del plazo de diez. ¿Qué decide el árbitro? | D12: Permite que el suplente entre en el terreno de juego. | E12: No permite que el suplente entre hasta que transcurra un minuto desde la reanudación. | F12: Amonesta al jugador sustituido por retrasar la reanudación. | G12: A | H12: Como la finalidad de la cuenta atrás es impedir pérdidas de tiempo, si el jugador sustituido está muy cerca de la línea o cruzándola al terminar la cuenta, se permite que el suplente entre. | I12: Regla 3.3 / Procedimiento de sustitución | J12: 3
A13: RJ3-013 | B13: situacion | C13: Durante una sustitución, ¿por dónde debe entrar el jugador suplente al terreno de juego, con carácter general? | D13: Por la línea de banda a la altura de la línea media, tras recibir la señal del árbitro, salvo excepciones autorizadas por él. | E13: Por cualquier punto de la línea de banda, tras recibir la señal del árbitro, salvo excepciones autorizadas por él. | F13: Por la zona donde se encuentre el banquillo de su equipo, sin necesidad de señal del árbitro. | G13: A | H13: Con carácter general, el suplente solo puede entrar al terreno de juego por la línea de banda a la altura de la línea media (línea central), tras recibir la señal del árbitro, salvo que este autorice otra ubicación. | I13: Regla 3 | J13: 2
... A89: RJ3-093 | B89: directa | C89: ¿Puede un jugador de campo intercambiar su puesto con el guardameta durante una interrupción del juego sin informar antes al árbitro? | D89: No, debe informarse al árbitro antes de que se produzca el cambio. | E89: Sí, si el cambio se realiza durante una interrupción del juego. | F89: Sí, si se informa al árbitro en la siguiente interrupción del juego. | G89: A | H89: El intercambio de puesto entre un jugador de campo y el guardameta requiere comunicación previa e informar al árbitro antes de que se produzca. | I89: Regla 3 | J89: 2

Sheet Regla 4
A1: ID | B1: Tipo | C1: Enunciado | D1: Opción A | E1: Opción B | F1: Opción C | G1: Correcta | H1: Explicación | I1: Referencia | J1: Dificultad
A2: RJ3-012 | B2: directa | C2: ¿Es obligatorio que el capitán de un equipo lleve un brazalete distintivo? | D2: Sí, es una obligación general, pero su diseño puede quedar sujeto al reglamento de la competición. | E2: Sí, en todas las categorías, con un diseño fijado por las Reglas de Juego. | F2: No es obligatorio, quedando su uso a la libre elección de cada capitán antes del partido. | G2: A | H2: El capitán debe llevar un brazalete distintivo; su diseño concreto (colores, inscripciones) puede quedar sujeto a lo que autorice el reglamento de cada competición. | I2: Regla 4 | J2: 1
A3: RJ4-001 | B3: situacion | C3: Un jugador sale del terreno de juego para cambiarse la camiseta manchada de sangre. ¿Cuándo podrá volver al terreno de juego? | D3: Con permiso del árbitro, tras revisar su equipamiento un miembro del equipo arbitral, aunque el juego no esté detenido. | E3: Con permiso del árbitro, tras revisar su equipamiento un miembro del equipo arbitral, y solo con el juego detenido. | F3: En cuanto se cambie la camiseta, sin que sea necesario revisar su equipamiento ni el permiso del árbitro. | G3: A | H3: Regla 4 (pág. 40): el jugador debe someter el equipamiento al control de un miembro del equipo arbitral y volver a entrar únicamente con el permiso del árbitro, «el cual puede concederse durante el juego». | I3: Regla 4 | J3: 3
A4: RJ4-002 | B4: situacion | C4: Un jugador que había salido del terreno de juego para arreglar su camiseta manchada de sangre reingresa sin que el juego esté detenido y sin permiso del árbitro. ¿Qué decisión toma el árbitro? | D4: Amonesta al jugador y concede tiro libre indirecto en el lugar donde estaba el balón cuando se detiene el juego, salvo interferencia, en cuyo caso será directo o penal desde el lugar de la interferencia. | E4: Amonesta al jugador y concede tiro libre directo en el lugar donde estaba el balón cuando se detiene el juego, salvo interferencia, en cuyo caso será indirecto desde el lugar de la interferencia. | F4: Expulsa al jugador y concede tiro libre indirecto en el lugar donde estaba el balón cuando se detiene el juego, salvo interferencia, en cuyo caso será directo o penal desde el lugar de la interferencia. | G4: A | H4: Reingresar sin autorización conlleva amonestación y tiro libre indirecto donde estaba el balón al detenerse el juego, salvo que hubiera interferencia, que se sanciona con directo o penal desde el lugar de la interferencia. | I4: Regla 3 / Regla 4 | J4: 4
A5: RJ4-003 | B5: situacion | C5: Antes del partido, el delegado local comunica que el capitán llevará un brazalete con los colores de la bandera nacional y la letra 'C'. ¿Qué debe decidir el árbitro? | D5: Permitirlo si lo autoriza el reglamento de la competición. | E5: Permitirlo si cumple las estipulaciones de la Regla 4 sobre el equipamiento. | F5: No permitirlo, porque el brazalete debe ser de un solo color. | G5: A | H5: El uso de brazaletes de capitán con diseños o colores concretos queda sujeto a lo que permita el reglamento de la propia competición. | I5: Regla 4 | J5: 4
A6: RJ4-004 | B6: directa | C6: Según la Regla 4, los eslóganes, mensajes e imágenes autorizados deberán aparecer únicamente: | D6: En el frontal de la camiseta y del pantalón, o en el brazalete. | E6: En el frontal de la camiseta o en el brazalete. | F6: En el frontal del pantalón o en las mangas. | G6: B | H6: Regla 4 (pág. 39): «Los eslóganes autorizados, los mensajes y las imágenes deberán aparecer únicamente en el frontal de la camiseta o en el brazalete». | I6: Regla 4 | J6: 1
A7: RJ4-006 | B7: situacion | C7: Durante la revisión de indumentaria previa al partido, ¿puede el árbitro exigir que se retire un elemento no reglamentario del uniforme? | D7: Sí, forma parte de sus obligaciones inspeccionar la indumentaria de los jugadores antes del partido. | E7: No, esa función corresponde al delegado de campo de cada equipo antes del partido. | F7: No, la revisión de indumentaria corresponde al cuarto árbitro, no al árbitro principal. | G7: A | H7: Entre las obligaciones del árbitro antes del partido está inspeccionar el terreno, los balones y también verificar que el equipamiento de los jugadores cumple la normativa. | I7: Regla 4 / Regla 5 | J7: 3
A8: RJ4-007 | B8: situacion | C8: Un jugador sale al terreno de juego con unas espinilleras que no ofrecen un grado de protección razonable. El árbitro... | D8: No le permite participar hasta que corrija su equipamiento. | E8: Le permite participar, porque la elección de las espinilleras es libre. | F8: Le permite participar, pero lo amonesta por su equipamiento. | G8: A | H8: El árbitro debe verificar que el equipamiento obligatorio, incluidas las espinilleras, ofrece una protección razonable antes de permitir la participación del jugador. | I8: Regla 4 | J8: 2
A9: RJ4-008 | B9: directa | C9: ¿Puede un jugador llevar una camiseta interior de un color distinto a la manga principal de la camiseta de juego? | D9: Debe coincidir sustancialmente con el color principal de la manga de la camiseta. | E9: Puede ser de cualquier color, ya que las Reglas de Juego no regulan las prendas interiores. | F9: Está prohibida cualquier prenda interior bajo la camiseta. | G9: A | H9: La Regla 4 exige que la camiseta interior coincida, en su color principal, con el color dominante de la manga de la camiseta de juego. | I9: Regla 4 | J9: 2
A10: RJ4-009 | B10: situacion | C10: Durante una jugada, un jugador pierde accidentalmente la camiseta y sigue jugando. El árbitro... | D10: No detiene el juego; lo corregirá en la próxima detención. | E10: Detiene el juego de inmediato y amonesta al jugador. | F10: Detiene el juego de inmediato y concede tiro libre indirecto. | G10: A | H10: Regla 4.6: «En caso de infracción de esta regla, no es necesario detener el juego»; el árbitro ordenará al jugador que corrija su equipamiento y saldrá del terreno de juego cuando se detenga el juego, a menos que ya lo haya corregido. | I10: Regla 4.6 | J10: 1
A11: RJ4-011 | B11: situacion | C11: Un jugador quiere jugar con un accesorio que no es peligroso, cubierto de forma segura con cinta adhesiva. Según la Regla 4 (2026/27): | D11: Puede llevarlo. | E11: Debe quitárselo. | F11: Solo si la cinta es del color de la prenda. | G11: A | H11: Regla 4 (pág. 37): «Se permite llevar accesorios siempre y cuando no sean peligrosos y estén cubiertos de forma segura». Las prendas u objetos peligrosos sí deben quitarse: no basta con cubrirlos con cinta adhesiva. | I11: Regla 4 / Seguridad | J11: 2
A12: RJ4-013 | B12: situacion | C12: Un jugador lleva un accesorio prohibido y no puede o no quiere quitárselo cuando el árbitro se lo ordena. El árbitro... | D12: Le ordena que salga del terreno de juego en la próxima detención del juego. | E12: Le permite seguir jugando y lo hace constar en el acta del partido. | F12: Detiene el juego de inmediato y lo expulsa por no acatar su orden. | G12: A | H12: Si el jugador no puede o no quiere acatar la orden de quitarse el objeto, el árbitro deberá ordenarle que salga del terreno de juego en la próxima detención del juego. | I12: Regla 4 / Seguridad | J12: 2
